Workbook

Sheet June-26
A1: MONTHLY TEST PERFORMED STATEMENT SHOWING PATHOLOGY DEPARTMENT MORNING EVENING AND NIGHT SHIFT GHULAM MUHAMMAD MAHAR MEDICAL COLLEGE SUKKUR MONTH OF JUNE 2026 | AM1: MONTHLY POSITIVE CASES STATEMENT SHOWING PATHOLOGY DEPARTMENT GHULAM MUHAMMAD MAHAR MEDICAL COLLEGE HOSPITAL SUKKUR MONTH OF MAY 2026
Z2: LIPID PROFILE
A3: Date | B3: CBC | C3: BT CT | D3: MP ICT | E3: H. Pylori | F3: PT INR | G3: APTT | H3: URINE DR | I3: URINE PT | J3: BSR | K3: UREA | L3: CRETININE | M3: LFT | N3: ELECTROLYTES | O3: HBs ICT | P3: HCV ICT | Q3: HIV ICT | R3: B. Group | S3: VDRL | T3: RA | U3: ASO TITER | V3: DENGE NS1 | W3: DENGE IGM | X3: URIC ACID | Y3: HBA 1c | Z3: S. CHOLESTROL | AA3: T.G | AB3: HDL | AC3: LDL | AD3: S. CALCIUM | AE3: S. AMYLYSIS | AF3: S. ALBUMIN | AG3: Body Fluid | AH3: ABG S | AI3: CBC TUBES | AJ3: GEL TUBES | AK3: PT TUBES | AL3: HAPRIN TUBES | AM3: Date | AN3: HBs ICT +VE | AO3: HCV ICT +VE | AP3: HIV ICT +VE | AQ3: VDRL +VE | AR3: DENGUE NS1 | AS3: DENGUE IgG/IGM | AT3: MP ICT +VE | AU3: PV | AV3: PF | AW3: MIX
A4: 01-06-2026 | B4: 346 | C4: 8 | D4: 105 | E4: 7 | F4: 42 | G4: =F4 -> 42 | H4: 10 | I4: 1 | J4: 92 | K4: 172 | L4: =K4 -> 172 | M4: 192 | N4: 112 | O4: 330 | P4: 330 | Q4: 45 | R4: 6 | S4: 33 | T4: 8 | U4: 0 | V4: 5 | W4: 0 | X4: 15 | Y4: 0 | Z4: 10 | AA4: =Z4 -> 10 | AB4: =Z4 -> 10 | AC4: =Z4 -> 10 | AD4: 15 | AE4: 8 | AF4: 45 | AG4: 0 | AH4: 18 | AI4: =B4+15 -> 361 | AJ4: =AI4/100*70 -> 252.7 | AK4: =G4+5 -> 47 | AL4: =2+AH4 -> 20 | AM4: 01-06-2026 | AN4: 4 | AO4: 9
A5: 02-06-2026 | B5: 341 | C5: 8 | D5: 116 | E5: 10 | F5: 45 | G5: =F5 -> 45 | H5: 16 | I5: 1 | J5: 78 | K5: 192 | L5: =K5 -> 192 | M5: 210 | N5: 110 | O5: 327 | P5: 327 | Q5: 51 | R5: 10 | S5: 27 | T5: 10 | U5: 0 | V5: 12 | W5: 0 | X5: 15 | Y5: 0 | Z5: 11 | AA5: =Z5 -> 11 | AB5: =Z5 -> 11 | AC5: =Z5 -> 11 | AD5: 9 | AE5: 7 | AF5: 42 | AG5: 0 | AH5: 15 | AI5: =B5+15 -> 356 | AJ5: =AI5/100*70 -> 249.2 | AK5: =G5+5 -> 50 | AL5: =2+AH5 -> 17 | AM5: 02-06-2026 | AN5: 3 | AO5: 6
A6: 03-06-2026 | B6: 337 | C6: 10 | D6: 100 | E6: 10 | F6: 38 | G6: =F6 -> 38 | H6: 0 | I6: 0 | J6: 87 | K6: 198 | L6: =K6 -> 198 | M6: 218 | N6: 95 | O6: 281 | P6: 281 | Q6: 42 | R6: 7 | S6: 26 | T6: 10 | U6: 0 | V6: 10 | W6: 0 | X6: 18 | Y6: 0 | Z6: 10 | AA6: =Z6 -> 10 | AB6: =AA6 -> 10 | AC6: =AB6 -> 10 | AD6: 15 | AE6: 10 | AF6: 38 | AG6: 0 | AH6: 18 | AI6: =B6+15 -> 352 | AJ6: =AI6/100*70 -> 246.4 | AK6: =G6+5 -> 43 | AL6: =2+AH6 -> 20 | AM6: 03-06-2026 | AN6: 3 | AO6: 11
A7: 04-06-2026 | B7: 345 | C7: 10 | D7: 105 | E7: 8 | F7: 45 | G7: =F7 -> 45 | H7: 20 | I7: 0 | J7: 75 | K7: 199 | L7: =K7 -> 199 | M7: 207 | N7: 85 | O7: 281 | P7: 281 | Q7: 46 | R7: 7 | S7: 25 | T7: 8 | U7: 0 | V7: 5 | W7: 0 | X7: 15 | Y7: 0 | Z7: 11 | AA7: =Z7 -> 11 | AB7: =AA7 -> 11 | AC7: =AB7 -> 11 | AD7: 10 | AE7: 7 | AF7: 41 | AG7: 0 | AH7: 18 | AI7: =B7+15 -> 360 | AJ7: =AI7/100*70 -> 252 | AK7: =G7+5 -> 50 | AL7: =2+AH7 -> 20 | AM7: 04-06-2026 | AO7: 11 | AT7: 1 | AU7: 1
A8: 05-06-2026 | B8: 338 | C8: 7 | D8: 88 | E8: 6 | F8: 42 | G8: =F8 -> 42 | H8: 5 | I8: 0 | J8: 64 | K8: 178 | L8: =K8 -> 178 | M8: 210 | N8: 78 | O8: 0 | P8: 0 | Q8: 35 | R8: 6 | S8: 10 | T8: 7 | U8: 0 | V8: 3 | W8: 0 | X8: 10 | Y8: 0 | Z8: 10 | AA8: =Z8 -> 10 | AB8: =AA8 -> 10 | AC8: =AB8 -> 10 | AD8: 11 | AE8: 7 | AF8: 38 | AG8: 0 | AH8: 0 | AI8: =B8+15 -> 353 | AJ8: =AI8/100*70 -> 247.1 | AK8: =G8+5 -> 47 | AL8: =2+AH8 -> 2 | AM8: 05-06-2026 | AN8: 1 | AT8: 2 | AU8: 1 | AV8: 1
A9: 06-06-2026 | B9: 337 | C9: 6 | D9: 105 | E9: 7 | F9: 42 | G9: =F9 -> 42 | H9: 10 | I9: 2 | J9: 65 | K9: 190 | L9: =K9 -> 190 | M9: 210 | N9: 78 | O9: 0 | P9: 199 | Q9: 32 | R9: 6 | S9: 4 | T9: 7 | U9: 0 | V9: 10 | W9: 0 | X9: 11 | Y9: 0 | Z9: 15 | AA9: =Z9 -> 15 | AB9: =AA9 -> 15 | AC9: =AB9 -> 15 | AD9: 10 | AE9: 8 | AF9: 42 | AG9: 0 | AH9: 7 | AI9: =B9+15 -> 352 | AJ9: =AI9/100*70 -> 246.4 | AK9: =G9+5 -> 47 | AL9: =2+AH9 -> 9 | AM9: 06-06-2026 | AO9: 10
A10: 07-06-2026 | B10: 95 | C10: 6 | D10: 40 | E10: 0 | F10: 22 | G10: =F10 -> 22 | H10: 0 | I10: 0 | J10: 18 | K10: 75 | L10: =K10 -> 75 | M10: 78 | N10: 32 | O10: 0 | P10: 75 | Q10: 10 | R10: 0 | S10: 0 | T10: 10 | U10: 0 | V10: 6 | W10: 0 | X10: 5 | Y10: 0 | Z10: 5 | AA10: =Z10 -> 5 | AB10: =AA10 -> 5 | AC10: =AB10 -> 5 | AD10: 4 | AE10: 3 | AF10: 10 | AG10: 0 | AH10: 16 | AI10: =B10+15 -> 110 | AJ10: =AI10/100*70 -> 77 | AK10: =G10+5 -> 27 | AL10: =2+AH10 -> 18 | AM10: 07-06-2026 | AO10: 5
A11: 08-06-2026 | B11: 345 | C11: 7 | D11: 111 | E11: 6 | F11: 45 | G11: =F11 -> 45 | H11: 12 | I11: 4 | J11: 66 | K11: 190 | L11: =K11 -> 190 | M11: 0 | N11: 215 | O11: 0 | P11: 291 | Q11: 50 | R11: 5 | S11: 26 | T11: 8 | U11: 0 | V11: 10 | W11: 0 | X11: 15 | Y11: 0 | Z11: 11 | AA11: =Z11 -> 11 | AB11: =AA11 -> 11 | AC11: =AB11 -> 11 | AD11: 8 | AE11: 7 | AF11: 45 | AG11: 1 | AH11: 26 | AI11: =B11+15 -> 360 | AJ11: =AI11/100*70 -> 252 | AK11: =G11+5 -> 50 | AL11: =2+AH11 -> 28 | AM11: 08-06-2026 | AO11: 21 | AT11: 1 | AV11: 1
A12: 09-06-2026 | B12: 340 | C12: 7 | D12: 116 | E12: 10 | F12: 45 | G12: =F12 -> 45 | H12: 4 | I12: 1 | J12: 76 | K12: 210 | L12: =K12 -> 210 | M12: 0 | N12: 72 | O12: 317 | P12: 317 | Q12: 45 | R12: 6 | S12: 26 | T12: 7 | U12: 0 | V12: 14 | W12: 0 | X12: 12 | Y12: 0 | Z12: 9 | AA12: =Z12 -> 9 | AB12: =AA12 -> 9 | AC12: =AB12 -> 9 | AD12: 11 | AE12: 7 | AF12: 45 | AG12: 0 | AH12: 11 | AI12: =B12+15 -> 355 | AJ12: =AI12/100*70 -> 248.5 | AK12: =G12+5 -> 50 | AL12: =2+AH12 -> 13 | AM12: 09-06-2026 | AN12: 1 | AO12: 13
A13: 10-06-2026 | B13: 345 | C13: 6 | D13: 116 | E13: 6 | F13: 42 | G13: =F13 -> 42 | H13: 19 | I13: 1 | J13: 65 | K13: 190 | L13: =K13 -> 190 | M13: 0 | N13: 77 | O13: 250 | P13: 250 | Q13: 52 | R13: 6 | S13: 28 | T13: 6 | U13: 0 | V13: 9 | W13: 0 | X13: 11 | Y13: 0 | Z13: 7 | AA13: =Z13 -> 7 | AB13: =AA13 -> 7 | AC13: =AB13 -> 7 | AD13: 9 | AE13: 6 | AF13: 52 | AG13: 0 | AH13: 23 | AI13: =B13+15 -> 360 | AJ13: =AI13/100*70 -> 252 | AK13: =G13+5 -> 47 | AL13: =2+AH13 -> 25 | AM13: 10-06-2026 | AN13: 10 | AO13: 7
A14: 11-06-2026 | B14: 358 | C14: 7 | D14: 105 | E14: 7 | F14: 45 | G14: =F14 -> 45 | H14: 10 | I14: 3 | J14: 78 | K14: 198 | L14: =K14 -> 198 | M14: 0 | N14: 78 | O14: 258 | P14: 258 | Q14: 42 | R14: 6 | S14: 25 | T14: 6 | U14: 0 | V14: 7 | W14: 0 | X14: 15 | Y14: 0 | Z14: 10 | AA14: =Z14 -> 10 | AB14: =AA14 -> 10 | AC14: =AB14 -> 10 | AD14: 8 | AE14: 6 | AF14: 45 | AG14: 1 | AH14: 15 | AI14: =B14+15 -> 373 | AJ14: =AI14/100*70 -> 261.1 | AK14: =G14+5 -> 50 | AL14: =2+AH14 -> 17 | AM14: 11-06-2026 | AN14: 5 | AO14: 7
A15: 12-06-2026 | B15: 336 | C15: 7 | D15: 90 | E15: 5 | F15: 42 | G15: =F15 -> 42 | H15: 5 | I15: 1 | J15: 68 | K15: 172 | L15: =K15 -> 172 | M15: 0 | N15: 92 | O15: 198 | P15: 198 | Q15: 41 | R15: 5 | S15: 18 | T15: 10 | U15: 0 | V15: 6 | W15: 0 | X15: 10 | Y15: 0 | Z15: 9 | AA15: =Z15 -> 9 | AB15: =AA15 -> 9 | AC15: =AB15 -> 9 | AD15: 8 | AE15: 7 | AF15: 48 | AG15: 0 | AH15: 19 | AI15: =B15+15 -> 351 | AJ15: =AI15/100*70 -> 245.7 | AK15: =G15+5 -> 47 | AL15: =2+AH15 -> 21 | AM15: 12-06-2026 | AN15: 3 | AO15: 11
A16: 13-06-2026 | B16: 368 | C16: 6 | D16: 110 | E16: 7 | F16: 52 | G16: =F16 -> 52 | H16: 14 | I16: 4 | J16: 79 | K16: 210 | L16: =K16 -> 210 | M16: 0 | N16: 105 | O16: 260 | P16: 260 | Q16: 51 | R16: 6 | S16: 25 | T16: 8 | U16: 0 | V16: 9 | W16: 0 | X16: 12 | Y16: 0 | Z16: 7 | AA16: =Z16 -> 7 | AB16: =AA16 -> 7 | AC16: =AB16 -> 7 | AD16: 6 | AE16: 5 | AF16: 38 | AG16: 1 | AH16: 27 | AI16: =B16+15 -> 383 | AJ16: =AI16/100*70 -> 268.1 | AK16: =G16+5 -> 57 | AL16: =2+AH16 -> 29 | AM16: 13-06-2026 | AN16: 5 | AO16: 12
A17: 14-06-2026 | B17: 110 | C17: 2 | D17: 55 | E17: 0 | F17: 18 | G17: =F17 -> 18 | H17: 0 | I17: 0 | J17: 22 | K17: 85 | L17: =K17 -> 85 | M17: 0 | N17: 45 | O17: 100 | P17: 100 | Q17: 10 | R17: 0 | S17: 0 | T17: 0 | U17: 0 | V17: 7 | W17: 0 | X17: 5 | Y17: 0 | Z17: 5 | AA17: =Z17 -> 5 | AB17: =AA17 -> 5 | AC17: =AB17 -> 5 | AD17: 3 | AE17: 2 | AF17: 10 | AG17: 1 | AH17: 11 | AI17: =B17+15 -> 125 | AJ17: =AI17/100*70 -> 87.5 | AK17: =G17+5 -> 23 | AL17: =2+AH17 -> 13 | AM17: 14-06-2026 | AN17: 2 | AO17: 5 | AP17: 2 | AT17: 2 | AU17: 1 | AV17: 1
A18: 15-06-2026 | B18: 370 | C18: 10 | D18: 55 | E18: 6 | F18: 60 | G18: =F18 -> 60 | H18: 13 | I18: 5 | J18: 78 | K18: 210 | L18: =K18 -> 210 | M18: 0 | N18: 145 | O18: 315 | P18: 315 | Q18: 49 | R18: 6 | S18: 30 | T18: 0 | U18: 0 | V18: 11 | W18: 0 | X18: 15 | Y18: 0 | Z18: 11 | AA18: =Z18 -> 11 | AB18: =AA18 -> 11 | AC18: =AB18 -> 11 | AD18: 10 | AE18: 7 | AF18: 60 | AG18: 1 | AH18: 17 | AI18: =B18+15 -> 385 | AJ18: =AI18/100*70 -> 269.5 | AK18: =G18+5 -> 65 | AL18: =2+AH18 -> 19 | AM18: 15-06-2026 | AN18: 6 | AO18: 15
A19: 16-06-2026 | B19: 370 | C19: 8 | D19: 15 | E19: 8 | F19: 60 | G19: =F19 -> 60 | H19: 13 | I19: 0 | J19: 74 | K19: 198 | L19: =K19 -> 198 | M19: 0 | N19: 84 | O19: 243 | P19: 243 | Q19: 44 | R19: 8 | S19: 14 | T19: 0 | U19: 0 | V19: 12 | W19: 0 | X19: 12 | Y19: 0 | Z19: 8 | AA19: =Z19 -> 8 | AB19: =AA19 -> 8 | AC19: =AB19 -> 8 | AD19: 9 | AE19: 7 | AF19: 45 | AG19: 0 | AH19: 21 | AI19: =B19+15 -> 385 | AJ19: =AI19/100*70 -> 269.5 | AK19: =G19+5 -> 65 | AL19: =2+AH19 -> 23 | AM19: 16-06-2026 | AN19: 7 | AO19: 9 | AP19: 1
A20: 17-06-2026 | B20: 365 | C20: 6 | D20: 10 | E20: 6 | F20: 65 | G20: =F20 -> 65 | H20: 6 | I20: 4 | J20: 84 | K20: 210 | L20: =K20 -> 210 | M20: 0 | N20: 105 | O20: 258 | P20: 258 | Q20: 54 | R20: 6 | S20: 22 | T20: 0 | U20: 0 | V20: 10 | W20: 0 | X20: 12 | Y20: 0 | Z20: 11 | AA20: =Z20 -> 11 | AB20: =AA20 -> 11 | AC20: =AB20 -> 11 | AD20: 10 | AE20: 8 | AF20: 58 | AG20: 0 | AH20: 8 | AI20: =B20+15 -> 380 | AJ20: =AI20/100*70 -> 266 | AK20: =G20+5 -> 70 | AL20: =2+AH20 -> 10 | AM20: 17-06-2026 | AN20: 8 | AO20: 18
A21: 18-06-2026 | B21: 335 | C21: 7 | D21: 20 | E21: 6 | F21: 65 | G21: =F21 -> 65 | H21: 7 | I21: 2 | J21: 65 | K21: 150 | L21: =K21 -> 150 | M21: 0 | N21: 105 | O21: 235 | P21: 191 | Q21: 51 | R21: 6 | S21: 14 | T21: 0 | U21: 0 | V21: 5 | W21: 0 | X21: 12 | Y21: 0 | Z21: 7 | AA21: =Z21 -> 7 | AB21: =AA21 -> 7 | AC21: =AB21 -> 7 | AD21: 9 | AE21: 4 | AF21: 45 | AG21: 0 | AH21: 0 | AI21: 400 | AJ21: 300 | AK21: =G21+5 -> 70 | AL21: =2+AH21 -> 2 | AM21: 18-06-2026 | AN21: 7 | AO21: 11
A22: 19-06-2026 | B22: 336 | C22: 6 | D22: 8 | E22: 5 | F22: 70 | G22: =F22 -> 70 | H22: 5 | I22: 0 | J22: 75 | K22: 120 | L22: =K22 -> 120 | M22: 0 | N22: 110 | O22: 180 | P22: 125 | Q22: 37 | R22: 6 | S22: 12 | T22: 0 | U22: 0 | V22: 11 | W22: 0 | X22: 11 | Y22: 0 | Z22: 8 | AA22: =Z22 -> 8 | AB22: =AA22 -> 8 | AC22: =AB22 -> 8 | AD22: 11 | AE22: 7 | AF22: 55 | AG22: 0 | AH22: 0 | AI22: 479 | AJ22: 380 | AK22: =G22+5 -> 75 | AL22: =2+AH22 -> 2 | AM22: 19-06-2026 | AN22: 2 | AO22: 9
A23: 20-06-2026 | B23: 332 | C23: 4 | D23: 15 | E23: 5 | F23: 65 | G23: =F23 -> 65 | H23: 12 | I23: 3 | J23: 74 | L23: 0 | M23: 0 | N23: 105 | O23: 100 | P23: 0 | Q23: 45 | R23: 4 | S23: 10 | T23: 0 | U23: 0 | V23: 7 | W23: 0 | X23: 12 | Y23: 0 | Z23: 8 | AA23: =Z23 -> 8 | AB23: =AA23 -> 8 | AC23: =AB23 -> 8 | AD23: 9 | AE23: 4 | AF23: 52 | AG23: 0 | AH23: 0 | AI23: 421 | AJ23: 360 | AK23: =G23+5 -> 70 | AL23: =2+AH23 -> 2 | AM23: 20-06-2026 | AN23: 1 | AO23: 1
A24: 21-06-2026 | B24: 110 | C24: 2 | D24: 10 | E24: 2 | F24: 22 | G24: =F24 -> 22 | H24: 0 | I24: 0 | J24: 19 | K24: 55 | L24: =K24 -> 55 | M24: 25 | N24: 27 | O24: 50 | P24: 25 | Q24: 12 | R24: 0 | S24: 0 | T24: 2 | U24: 0 | V24: 5 | W24: 0 | X24: 6 | Y24: 0 | Z24: 4 | AA24: =Z24 -> 4 | AB24: =AA24 -> 4 | AC24: =AB24 -> 4 | AD24: 5 | AE24: 3 | AF24: 15 | AG24: 0 | AH24: 0 | AI24: 420 | AJ24: 340 | AK24: =G24+5 -> 27 | AL24: =2+AH24 -> 2 | AM24: 21-06-2026 | AN24: 1 | AO24: 1
A25: 22-06-2026 | B25: 316 | C25: 6 | D25: 69 | E25: 7 | F25: 62 | G25: =F25 -> 62 | H25: 8 | I25: 1 | J25: 81 | K25: 190 | L25: =K25 -> 190 | M25: 216 | N25: 80 | O25: 274 | P25: 274 | Q25: 50 | R25: 4 | S25: 13 | T25: 2 | U25: 0 | V25: 12 | W25: 0 | X25: 12 | Y25: 0 | Z25: 10 | AA25: =Z25 -> 10 | AB25: =AA25 -> 10 | AC25: =AB25 -> 10 | AD25: 7 | AE25: 4 | AF25: 65 | AG25: 1 | AH25: 17 | AI25: =B25+15 -> 331 | AJ25: =AI25/100*70 -> 231.7 | AK25: =G25+5 -> 67 | AL25: =2+AH25 -> 19 | AM25: 22-06-2026 | AN25: 13 | AO25: 16 | AP25: 1
A26: 23-06-2026 | B26: 265 | C26: 7 | D26: 98 | E26: 6 | F26: 55 | G26: =F26 -> 55 | H26: 14 | I26: 2 | J26: 64 | K26: 15 | L26: =K26 -> 15 | M26: 215 | N26: 103 | O26: 175 | P26: 175 | Q26: 50 | R26: 6 | S26: 21 | T26: 2 | U26: 0 | V26: 12 | W26: 0 | X26: 10 | Y26: 0 | Z26: 7 | AA26: =Z26 -> 7 | AB26: =AA26 -> 7 | AC26: =AB26 -> 7 | AD26: 8 | AE26: 7 | AF26: 55 | AG26: 0 | AH26: 11 | AI26: =B26+15 -> 280 | AJ26: =AI26/100*70 -> 196 | AK26: =G26+5 -> 60 | AL26: =2+AH26 -> 13 | AM26: 23-06-2026 | AN26: 6 | AO26: 11
A27: 24-06-2026 | B27: 316 | C27: 8 | D27: 95 | E27: 0 | F27: 42 | G27: =F27 -> 42 | H27: 7 | I27: 0 | J27: 65 | K27: 198 | L27: =K27 -> 198 | M27: 216 | N27: 113 | O27: 50 | P27: 50 | Q27: 52 | R27: 2 | S27: 21 | U27: 0 | V27: 7 | W27: 0 | X27: 12 | Y27: 0 | Z27: 8 | AA27: =Z27 -> 8 | AB27: =AA27 -> 8 | AC27: =AB27 -> 8 | AD27: 6 | AE27: 9 | AF27: 52 | AG27: 0 | AH27: 14 | AI27: =B27+15 -> 331 | AJ27: =AI27/100*70 -> 231.7 | AK27: =G27+5 -> 47 | AL27: =2+AH27 -> 16 | AM27: 24-06-2026 | AN27: 1 | AO27: 3
A28: 25-06-2026 | B28: 95 | C28: 4 | D28: 40 | E28: 0 | F28: 22 | G28: =F28 -> 22 | H28: 0 | I28: 0 | J28: 18 | K28: 65 | L28: =K28 -> 65 | M28: 72 | N28: 38 | O28: 65 | P28: 65 | Q28: 6 | R28: 0 | S28: 0 | T28: 0 | U28: 0 | V28: 4 | W28: 0 | X28: 4 | Y28: 0 | Z28: 2 | AA28: =Z28 -> 2 | AB28: =AA28 -> 2 | AC28: =AB28 -> 2 | AD28: 4 | AE28: 6 | AF28: 18 | AG28: 0 | AH28: 16 | AI28: =B28+15 -> 110 | AJ28: =AI28/100*70 -> 77 | AK28: =G28+5 -> 27 | AL28: =2+AH28 -> 18 | AM28: 25-06-2026 | AN28: 1 | AO28: 1
A29: 26-06-2026 | B29: 90 | C29: 3 | D29: 35 | E29: 0 | F29: 21 | G29: =F29 -> 21 | H29: 0 | I29: 0 | J29: 21 | K29: 64 | L29: =K29 -> 64 | M29: 69 | N29: 28 | O29: 25 | P29: 25 | Q29: 8 | R29: 0 | S29: 0 | T29: 0 | U29: 0 | V29: 4 | W29: 0 | X29: 5 | Y29: 0 | Z29: 3 | AA29: =Z29 -> 3 | AB29: =AA29 -> 3 | AC29: =AB29 -> 3 | AD29: 4 | AE29: 2 | AF29: 12 | AG29: 1 | AH29: 16 | AI29: =B29+15 -> 105 | AJ29: =AI29/100*70 -> 73.5 | AK29: =G29+5 -> 26 | AL29: =2+AH29 -> 18 | AM29: 26-06-2026 | AN29: 2 | AO29: 1
A30: 27-06-2026 | B30: 312 | C30: 6 | D30: 95 | E30: 0 | F30: 62 | G30: =F30 -> 62 | H30: 9 | I30: 2 | J30: 86 | K30: 192 | L30: =K30 -> 192 | M30: 210 | N30: 110 | O30: 40 | P30: 40 | Q30: 52 | R30: 0 | S30: 16 | T30: 0 | U30: 0 | V30: 10 | W30: 0 | X30: 15 | Y30: 0 | Z30: 11 | AA30: =Z30 -> 11 | AB30: =AA30 -> 11 | AC30: =AB30 -> 11 | AD30: 10 | AE30: 7 | AF30: 52 | AG30: 1 | AH30: 17 | AI30: =B30+15 -> 327 | AJ30: =AI30/100*70 -> 228.9 | AK30: =G30+5 -> 67 | AL30: =2+AH30 -> 19 | AM30: 27-06-2026 | AN30: 1 | AO30: 3
A31: 28-06-2026 | B31: 112 | C31: 4 | D31: 65 | E31: 0 | F31: 40 | G31: =F31 -> 40 | H31: 0 | I31: 0 | J31: 25 | K31: 66 | L31: =K31 -> 66 | M31: 75 | N31: 42 | O31: 25 | P31: 25 | Q31: 15 | R31: 0 | S31: 0 | T31: 0 | U31: 0 | V31: 6 | W31: 0 | X31: 5 | Y31: 0 | Z31: 4 | AA31: =Z31 -> 4 | AB31: =AA31 -> 4 | AC31: =AB31 -> 4 | AD31: 4 | AE31: 2 | AF31: 10 | AG31: 0 | AH31: 11 | AI31: =B31+15 -> 127 | AJ31: =AI31/100*70 -> 88.9 | AK31: =G31+5 -> 45 | AL31: =2+AH31 -> 13 | AM31: 28-06-2026 | AN31: 1 | AO31: 1 | AT31: 1 | AV31: 1
A32: 29-06-2026 | B32: 336 | C32: 5 | D32: 98 | E32: 6 | F32: 65 | G32: =F32 -> 65 | H32: 12 | I32: 4 | J32: 75 | K32: 192 | L32: =K32 -> 192 | M32: 215 | N32: 110 | O32: 50 | P32: 50 | Q32: 45 | R32: 0 | S32: 10 | T32: 0 | U32: 0 | V32: 8 | W32: 0 | X32: 9 | Y32: 0 | Z32: 11 | AA32: =Z32 -> 11 | AB32: =AA32 -> 11 | AC32: =AB32 -> 11 | AD32: 9 | AE32: 6 | AF32: 45 | AG32: 1 | AH32: 26 | AI32: =B32+15 -> 351 | AJ32: =AI32/100*70 -> 245.7 | AK32: =G32+5 -> 70 | AL32: =2+AH32 -> 28 | AM32: 29-06-2026 | AN32: 0 | AO32: 0 | AP32: 1 | AT32: 1 | AV32: 1
A33: 30-06-2026 | B33: 342 | C33: 7 | D33: 95 | E33: 7 | F33: 62 | G33: =F33 -> 62 | H33: 15 | I33: 3 | J33: 95 | K33: 210 | L33: =K33 -> 210 | M33: 222 | N33: 118 | O33: 250 | P33: 250 | Q33: 48 | R33: 0 | S33: 22 | T33: 0 | U33: 0 | V33: 10 | W33: 0 | X33: 15 | Y33: 0 | Z33: 9 | AA33: =Z33 -> 9 | AB33: =AA33 -> 9 | AC33: =AB33 -> 9 | AD33: 8 | AE33: 7 | AF33: 55 | AG33: 1 | AH33: 19 | AI33: =B33+15 -> 357 | AJ33: =AI33/100*70 -> 249.9 | AK33: =G33+5 -> 67 | AL33: =2+AH33 -> 21 | AM33: 30-06-2026 | AN33: 3 | AO33: 6 | AT33: 1 | AV33: 1
A34: TOTAL | B34: =SUM(B4:B33) -> 8743 | C34: =SUM(C4:C33) -> 190 | D34: =SUM(D4:D33) -> 2185 | E34: =SUM(E4:E33) -> 153 | F34: =SUM(F4:F33) -> 1403 | G34: =SUM(G4:G33) -> 1403 | H34: =SUM(H4:H33) -> 246 | I34: =SUM(I4:I33) -> 44 | ... AK34: =SUM(AK4:AK33) -> 1553 | AL34: =AH34+2 -> 419 | AM34: TOTAL | AN34: =SUM(AN4:AN33) -> 97 | AO34: =SUM(AO4:AO33) -> 234 | AP34: =SUM(AP4:AP33) -> 5 | AQ34: =SUM(AQ4:AQ33) -> 0 | AR34: =SUM(AR4:AR33) -> 0 | AS34: =SUM(AS4:AS33) -> 0 | AT34: =SUM(AT4:AT33) -> 9 | AU34: =SUM(AU4:AU33) -> 3 | ... AW34: =SUM(AW4:AW33) -> 0
H36: HCV+VE | I36: =AO34 -> 234 | K36: MALARIA ICT +VE | P36: DENGUE NS1 | R36: =AR34 -> 0 | T36: OPD | V36: 25752.65
C37: ABDUL SAMI SOOMRO | H37: HBSAG+VE | I37: =AN34 -> 97 | L37: PF | M37: =AV34 -> 6 | P37: DENGUE IGM | R37: =AS34 -> 0 | T37: INDORE | V37: 51505.3 | AD37: DR. IRSA KHUWAJA
C38: INCHARGE LAB TECH: | H38: HIV +VE | I38: =AP34 -> 5 | L38: PV | M38: =AU34 -> 3 | T38: TOTAL | V38: =SUM(V36:V37) -> 77257.95 | AD38: INCHARGE PATHOLOGY DEPARTMENT
C39: GMMMC HOSPITAL SUKKUR | H39: VDRL +VE | I39: =AQ34 -> 0 | L39: MIX | M39: =AW34 -> 0 | AD39: GMMMC HOSPITAL SUKKUR
L40: TOTAL | M40: =SUM(M37:M39) -> 9

Sheet Indent
A1: MONTHLY STOCK RECIVED STATEMENT SHOWING PATHOLOGY DEPARTMENT GHULAM MUHAMMAD MAHAR MEDICAL COLLEGE SUKKUR MONTH OF JUNE 2026
A2: S.# | B2: Description | C2: 1 | D2: 2 | E2: 3 | F2: 4 | G2: 5 | H2: 6 | I2: 7 | J2: 8 | K2: 9 | L2: 10 | M2: 11 | N2: 12 | O2: 13 | P2: 14 | Q2: 15 | R2: 16 | S2: 17 | T2: 18 | U2: 19 | V2: 20 | W2: 21 | X2: 22 | Y2: 23 | Z2: 24 | AA2: 25 | AB2: 26 | AC2: 27 | AD2: 28 | AE2: 29 | AF2: 30 | AG2: 31 | AH2: Total
A3: 1 | B3: CBC PACK (M) | C3: 350 | D3: 350 | H3: 350 | J3: 700 | L3: 350 | N3: 350 | O3: 350 | Q3: 350 | S3: 350 | T3: 350 | U3: 350 | V3: 350 | X3: 350 | AH3: =SUM(C3:AG3) -> 4900
A4: 2 | B4: MP ICT | C4: 100 | D4: 100 | E4: 100 | F4: 200 | H4: 200 | J4: 100 | K4: 100 | L4: 100 | M4: 200 | O4: 200 | R4: 100 | X4: 75 | AH4: =SUM(C4:AG4) -> 1575
A5: 3 | B5: HBs ICT | C5: 300 | D5: 300 | E5: 300 | F5: 250 | K5: 300 | L5: 250 | M5: 400 | O5: 350 | Q5: 250 | R5: 250 | S5: 250 | T5: 350 | V5: 175 | X5: 275 | AH5: =SUM(C5:AG5) -> 4000
A6: 4 | B6: HCV ICT | C6: 300 | D6: 300 | E6: 300 | F6: 250 | H6: 300 | J6: 300 | K6: 300 | L6: 250 | M6: 400 | O6: 350 | Q6: 250 | R6: 250 | S6: 250 | T6: 250 | X6: 275 | AH6: =SUM(C6:AG6) -> 4325
A7: 5 | B7: STD/HIV ICT | C7: 50 | D7: 50 | E7: 50 | F7: 100 | H7: 100 | J7: 50 | K7: 50 | L7: 50 | O7: 50 | Q7: 50 | R7: 50 | S7: 50 | T7: 50 | V7: 100 | X7: 50 | AH7: =SUM(C7:AG7) -> 900
A8: 6 | B8: VDRL | J8: 100 | L8: 50 | O8: 50 | R8: 50 | V8: 0 | X8: 50 | AH8: =SUM(C8:AG8) -> 300
A9: 7 | B9: H. Pylori | H9: 100 | AH9: =SUM(C9:AG9) -> 100
A10: 8 | B10: DENGE NS1 | D10: 30 | H10: 30 | K10: 30 | M10: 30 | U10: 30 | AH10: =SUM(C10:AG10) -> 150
A11: 9 | B11: DENGE IGM | AH11: =SUM(C11:AG11) -> 0
A12: 10 | B12: BSR | AH12: =SUM(C12:AG12) -> 0
A13: 11 | B13: UREA UV | K13: 1 | M13: 1 | O13: 1 | X13: 1 | AH13: =SUM(C13:AG13) -> 4
A14: 12 | B14: CRETININE | C14: 1 | K14: 1 | M14: 1 | O14: 1 | AH14: =SUM(C14:AG14) -> 4
A15: 13 | B15: UREA | AH15: =SUM(C15:AG15) -> 0
A16: 14 | B16: SGPT | C16: 1 | F16: 1 | X16: 1 | AH16: =SUM(C16:AG16) -> 3
A17: 15 | B17: ALKALINE | C17: 1 | X17: 1 | AH17: =SUM(C17:AG17) -> 2
A18: 16 | B18: T.G | D18: 1 | AH18: =SUM(C18:AG18) -> 1
A19: 17 | B19: HDL | D19: 1 | AH19: =SUM(C19:AG19) -> 1
A20: 18 | B20: LDL | D20: 1 | AH20: =SUM(C20:AG20) -> 1
A21: 19 | B21: Total Biluribin | F21: 1 | X21: 1 | AH21: =SUM(C21:AG21) -> 2
A22: 20 | B22: Direct Biluribin | C22: 1 | F22: 1 | X22: 1 | AH22: =SUM(C22:AG22) -> 3
A23: 21 | B23: ELECTROLYTES | J23: 1 | X23: 1 | AH23: =SUM(C23:AG23) -> 2
A24: 22 | B24: ANTI SERA SET | E24: 1 | X24: 1 | AH24: =SUM(C24:AG24) -> 2
A25: 23 | B25: PT INR | C25: 1 | J25: 1 | M25: 1 | O25: 1 | X25: 1 | AH25: =SUM(C25:AG25) -> 5
A26: 24 | B26: APTT | C26: 1 | J26: 1 | M26: 1 | O26: 1 | X26: 1 | AH26: =SUM(C26:AG26) -> 5
A27: 25 | B27: URINE DR | H27: 100 | Q27: 1 | X27: 1 | AH27: =SUM(C27:AG27) -> 102
A28: 26 | B28: URINE PT | AH28: =SUM(C28:AG28) -> 0
A29: 27 | B29: BT CT | AH29: =SUM(C29:AG29) -> 0
A30: 28 | B30: RA | AH30: =SUM(C30:AG30) -> 0
A31: 29 | B31: ASOT | AH31: =SUM(C31:AG31) -> 0
A32: 30 | B32: S. CUP | C32: 500 | D32: 500 | J32: 500 | K32: 500 | M32: 500 | O32: 500 | Q32: 500 | R32: 500 | S32: 500 | T32: 500 | V32: 500 | X32: 500 | AH32: =SUM(C32:AG32) -> 6000
A33: 31 | B33: URIC ACID | C33: 1 | M33: 1 | S33: 1 | AH33: =SUM(C33:AG33) -> 3
A34: 32 | B34: HBA 1C | AH34: =SUM(C34:AG34) -> 0
A35: 33 | B35: S. CHOLESTROL | C35: 1 | AH35: =SUM(C35:AG35) -> 1
A36: 34 | B36: S. CALCIUM | AH36: =SUM(C36:AG36) -> 0
A37: 35 | B37: S. AMYLASE | J37: 1 | Q37: 1 | AH37: =SUM(C37:AG37) -> 2
A38: 36 | B38: S. ALBUMIN | O38: 1 | X38: 1 | AH38: =SUM(C38:AG38) -> 2
A39: 37 | B39: CSF | AH39: =SUM(C39:AG39) -> 0
A40: 38 | B40: ABG S | H40: 200 | X40: 200 | AH40: =SUM(C40:AG40) -> 400
...

Sheet Indent (2)
A1: MONTHLY STOCK RECIVED STATEMENT SHOWING PATHOLOGY DEPARTMENT GHULAM MUHAMMAD MAHAR MEDICAL COLLEGE SUKKUR MONTH OF JUNE 2026
A2: S.# | B2: Description | C2: Total Indent | D2: Test Perfomance | E2: Balance
A3: 1 | B3: CBC PACK (M) | C3: =Indent!AH3 -> 4900 | D3: ='June-26'!B34 -> 8743 | E3: =C3-D3 -> -3843
A4: 2 | B4: MP ICT | C4: =Indent!AH4 -> 1575 | D4: ='June-26'!D34 -> 2185 | E4: =C4-D4 -> -610
A5: 3 | B5: HBs ICT | C5: =Indent!AH5 -> 4000 | D5: ='June-26'!O34 -> 4937 | E5: =C5-D5 -> -937
A6: 4 | B6: HCV ICT | C6: =Indent!AH6 -> 4325 | D6: ='June-26'!P34 -> 5278 | E6: =C6-D6 -> -953
A7: 5 | B7: STD/HIV ICT | C7: =Indent!AH7 -> 900 | D7: ='June-26'!Q34 -> 1170 | E7: =C7-D7 -> -270
A8: 6 | B8: VDRL | C8: =Indent!AH8 -> 300 | D8: ='June-26'!S34 -> 478 | E8: =C8-D8 -> -178
A9: 7 | B9: H. Pylori | C9: =Indent!AH9 -> 100 | D9: ='June-26'!E34 -> 153 | E9: =C9-D9 -> -53
A10: 8 | B10: DENGE NS1 | C10: =Indent!AH10 -> 150 | D10: ='June-26'!V34 -> 247 | E10: =C10-D10 -> -97
A11: 9 | B11: DENGE IGM | C11: =Indent!AH11 -> 0 | D11: ='June-26'!W34 -> 0 | E11: =C11-D11 -> 0
A12: 10 | B12: BSR | C12: =Indent!AH12 -> 0 | D12: ='June-26'!J34 -> 1932 | E12: =C12-D12 -> -1932
A13: 11 | B13: UREA UV | C13: =Indent!AH13 -> 4 | D13: ='June-26'!K34 -> 4594 | E13: =C13-D13 -> -4590
A14: 12 | B14: CRETININE | C14: =Indent!AH14 -> 4 | D14: ='June-26'!L34 -> 4594 | E14: =C14-D14 -> -4590
A15: 13 | B15: UREA | C15: =Indent!AH15 -> 0 | E15: =C15-D15 -> 0
A16: 14 | B16: GPT | C16: =Indent!AH16 -> 3 | D16: ='June-26'!M34 -> 2860 | E16: =C16-D16 -> -2857
A17: 15 | B17: ALK | C17: =Indent!AH17 -> 2 | D17: ='June-26'!M34 -> 2860 | E17: =C17-D17 -> -2858
A18: 16 | B18: Total Biluribin | C18: =Indent!AH21 -> 2 | D18: ='June-26'!M34 -> 2860 | E18: =C18-D18 -> -2858
A19: 17 | B19: Direct Biluribin | C19: =Indent!AH22 -> 3 | D19: ='June-26'!M34 -> 2860 | E19: =C19-D19 -> -2857
A20: 18 | B20: ELECTROLYTES | C20: =Indent!AH23 -> 2 | D20: ='June-26'!N34 -> 2697 | E20: =C20-D20 -> -2695
A21: 19 | B21: ANTI SERA SET | C21: =Indent!AH24 -> 2 | D21: ='June-26'!R34 -> 124 | E21: =C21-D21 -> -122
A22: 20 | B22: PT INR | C22: =Indent!AH25 -> 5 | D22: ='June-26'!F34 -> 1403 | E22: =C22-D22 -> -1398
A23: 21 | B23: APTT | C23: =Indent!AH26 -> 5 | D23: ='June-26'!G34 -> 1403 | E23: =C23-D23 -> -1398
A24: 22 | B24: URINE DR | C24: =Indent!AH27 -> 102 | D24: ='June-26'!H34 -> 246 | E24: =C24-D24 -> -144
A25: 23 | B25: URINE PT | C25: =Indent!AH28 -> 0 | D25: ='June-26'!I34 -> 44 | E25: =C25-D25 -> -44
A26: 24 | B26: BT CT | C26: =Indent!AH29 -> 0 | D26: ='June-26'!C34 -> 190 | E26: =C26-D26 -> -190
A27: 25 | B27: RA | C27: =Indent!AH30 -> 0 | E27: =C27-D27 -> 0
A28: 26 | B28: ASOT | C28: =Indent!AH31 -> 0 | E28: =C28-D28 -> 0
A29: 27 | B29: S. CUP | C29: =Indent!AH32 -> 6000 | E29: =C29-D29 -> 6000
A30: 28 | B30: URIC ACID | C30: =Indent!AH33 -> 3 | E30: =C30-D30 -> 3
A31: 29 | B31: HBA 1C | C31: =Indent!AH34 -> 0 | E31: =C31-D31 -> 0
A32: 30 | B32: S. CHOLESTROL | C32: =Indent!AH35 -> 1 | E32: =C32-D32 -> 1
A33: 31 | B33: S. CALCIUM | C33: =Indent!AH36 -> 0 | E33: =C33-D33 -> 0
A34: 32 | B34: S. AMYLYSIS | C34: =Indent!AH37 -> 2 | E34: =C34-D34 -> 2
A35: 33 | B35: S. ALBUMIN | C35: =Indent!AH38 -> 2 | E35: =C35-D35 -> 2
A36: 34 | B36: CSF | C36: =Indent!AH39 -> 0 | E36: =C36-D36 -> 0
A37: 35 | B37: ABG S | C37: =Indent!AH40 -> 400 | E37: =C37-D37 -> 400
A38: 36 | B38: CBC TUBES | C38: =Indent!AH41 -> 6600 | E38: =C38-D38 -> 6600 | F38: 0
A39: 37 | B39: GEL TUBES | C39: =Indent!AH42 -> 6000 | E39: =C39-D39 -> 6000 | F39: 0
A40: 38 | B40: PT TUBES | C40: =Indent!AH43 -> 800 | E40: =C40-D40 -> 800 | F40: 100
...

Sheet Sheet1
A1: MONTHLY STOCK RECIVED & PERFORMED STATEMENT SHOWING PATHOLOGY DEPARTMENT GHULAM MUHAMMAD MAHAR MEDICAL COLLEGE SUKKUR MONTH OF MAY 2026 | AA1: MONTHLY STOCK RECIVED & PERFORMED STATEMENT SHOWING PATHOLOGY DEPARTMENT GHULAM MUHAMMAD MAHAR MEDICAL COLLEGE SUKKUR MONTH OF APRIL 2026 | BA1: MONTHLY STOCK RECIVED & PERFORMED STATEMENT SHOWING PATHOLOGY DEPARTMENT GHULAM MUHAMMAD MAHAR MEDICAL COLLEGE SUKKUR MONTH OF APRIL 2026 | CA1: MONTHLY STOCK RECIVED & PERFORMED STATEMENT SHOWING PATHOLOGY DEPARTMENT GHULAM MUHAMMAD MAHAR MEDICAL COLLEGE SUKKUR MONTH OF APRIL 2026
A2: S.# | B2: Description | C2: Date: 01-06-2026 | F2: Date: 02-06-2026 | I2: Date: 03-06-2026 | L2: Date: 04-06-2026 | O2: Date: 05-06-2026 | R2: Date: 06-06-2026 | U2: Date: 07-06-2026 | X2: Date: 08-06-2026 | AA2: S.# | AB2: Description | AC2: Date: 09-06-2026 | AF2: Date: 10-06-2026 | AI2: Date: 11-06-2026 | AL2: Date: 12-06-2026 | AO2: Date: 13-06-2026 | AR2: Date: 14-06-2026 | AU2: Date: 15-06-2026 | AX2: Date: 16-06-2026 | BA2: S.# | BB2: Description | BC2: Date: 17-06-2026 | BF2: Date: 18-06-2026 | BI2: Date: 19-06-2026 | BL2: Date: 20-06-2026 | BO2: Date: 21-06-2026 | BR2: Date: 22-06-2026 | BU2: Date: 23-06-2026 | BX2: Date: 24-06-2026 | CA2: S.# | CB2: Description | CC2: Date: 25-06-2026 | CF2: Date: 26-06-2026 | CI2: Date: 27-06-2026 | CL2: Date: 28-06-2026 | CO2: Date: 29-06-2026 | CR2: Date: 30-06-2026 | CU2: Date: 31-06-2026 | CX2: Total Monthly Report
C3: Avaible | D3: Indent | E3: Test | F3: Avaible | G3: Indent | H3: Test | I3: Avaible | J3: Indent | K3: Test | L3: Avaible | M3: Indent | N3: Test | O3: Avaible | P3: Indent | Q3: Test | R3: Avaible | S3: Indent | T3: Test | U3: Avaible | V3: Indent | W3: Test | X3: Avaible | Y3: Indent | Z3: Test | AC3: Avaible | AD3: Indent | AE3: Test | AF3: Avaible | AG3: Indent | AH3: Test | AI3: Avaible | AJ3: Indent | AK3: Test | AL3: Avaible | AM3: Indent | AN3: Test | AO3: Avaible | AP3: Indent | AQ3: Test | AR3: Avaible | AS3: Indent | AT3: Test | AU3: Avaible | AV3: Indent | AW3: Test | AX3: Avaible | AY3: Indent | AZ3: Test | BC3: Avaible | BD3: Indent | BE3: Test | BF3: Avaible | BG3: Indent | BH3: Test | BI3: Avaible | BJ3: Indent | BK3: Test | BL3: Avaible | BM3: Indent | BN3: Test | BO3: Avaible | BP3: Indent | BQ3: Test | BR3: Avaible | BS3: Indent | BT3: Test | BU3: Avaible | BV3: Indent | BW3: Test | BX3: Avaible | BY3: Indent | BZ3: Test | CC3: Avaible | CD3: Indent | CE3: Test | CF3: Avaible | CG3: Indent | CH3: Test | CI3: Avaible | CJ3: Indent | CK3: Test | CL3: Avaible | CM3: Indent | CN3: Test | CO3: Avaible | CP3: Indent | CQ3: Test | CR3: Avaible | CS3: Indent | CT3: Test | CU3: Avaible | CV3: Indent | CW3: Test | CX3: Avaible Balance | CY3: Indent | CZ3: Test
A4: 1 | B4: CBC PACK (M) | C4: 161 | D4: 350 | F4: =C4+D4+-E4 -> 511 | G4: 0 | I4: =F4+G4-H4 -> 511 | J4: 500 | L4: =I4+J4+-K4 -> 1011 | M4: 0 | O4: =L4+M4-N4 -> 1011 | P4: 0 | R4: =O4+P4-Q4 -> 1011 | S4: 500 | U4: =R4+S4-T4 -> 1511 | V4: 500 | X4: =U4+V4-W4 -> 2011 | Y4: 500 | AA4: 1 | AB4: CBC PACK (M) | AC4: =X4+Y4-Z4 -> 2511 | AD4: 0 | AF4: =AC4+AD4-AE4 -> 2511 | AG4: 500 | AI4: =AF4+AG4-AH4 -> 3011 | AJ4: 500 | AL4: =AI4+AJ4-AK4 -> 3511 | AM4: 0 | AO4: =AL4+AM4-AN4 -> 3511 | AP4: 500 | AR4: =AO4+AP4-AQ4 -> 4011 | AS4: 500 | AU4: =AR4+AS4-AT4 -> 4511 | AX4: =AU4+AV4-AW4 -> 4511 | AY4: 500 | BA4: 1 | BB4: CBC PACK (M) | CA4: 1 | CB4: CBC PACK (M) | CX4: =CU4+CR4+CO4+CL4+CI4+CF4+CC4+BX4+BU4+BR4+BO4+BO4+BO4+BO4+BL4+BI4+BF4+BC4+AX4+AU4+AR4+AO4+AL4+AI4+AF4+AC4+X4+U4+R4+O4+L4+I4+F4+C4 -> 35826 | CY4: =CV4+CS4+CP4+CM4+CJ4+CG4+CD4+BY4+BV4+BS4+BP4+BP4+BP4+BP4+BM4+BJ4+BG4+BD4+AY4+AV4+AS4+AP4+AM4+AJ4+AG4+AD4+Y4+V4+S4+P4+M4+J4+G4+D4 -> 4850 | CZ4: =CW4+CT4+CQ4+CN4+CK4+CH4+CE4+BZ4+BW4+BT4+BQ4+BQ4+BQ4+BQ4+BN4+BK4+BH4+BE4+AZ4+AW4+AT4+AQ4+AN4+AK4+AH4+AE4+Z4+W4+T4+Q4+N4+K4+H4+E4 -> 0
A5: 2 | B5: MP ICT | C5: 25 | F5: =C5+D5+-E5 -> 25 | G5: 150 | I5: =F5+G5-H5 -> 175 | L5: =I5+J5+-K5 -> 175 | O5: =L5+M5-N5 -> 175 | R5: =O5+P5-Q5 -> 175 | S5: 75 | V5: 75 | Y5: 75 | AA5: 2 | AB5: MP ICT | AD5: 150 | AJ5: 150 | AP5: 100 | AS5: 100 | AV5: 100 | AY5: 200 | BA5: 2 | BB5: MP ICT | CA5: 2 | CB5: MP ICT | CX5: =CU5+CR5+CO5+CL5+CI5+CF5+CC5+BX5+BU5+BR5+BO5+BO5+BO5+BO5+BL5+BI5+BF5+BC5+AX5+AU5+AR5+AO5+AL5+AI5+AF5+AC5+X5+U5+R5+O5+L5+I5+F5+C5 -> 750 | CY5: =CV5+CS5+CP5+CM5+CJ5+CG5+CD5+BY5+BV5+BS5+BP5+BP5+BP5+BP5+BM5+BJ5+BG5+BD5+AY5+AV5+AS5+AP5+AM5+AJ5+AG5+AD5+Y5+V5+S5+P5+M5+J5+G5+D5 -> 1175 | CZ5: =CW5+CT5+CQ5+CN5+CK5+CH5+CE5+BZ5+BW5+BT5+BQ5+BQ5+BQ5+BQ5+BN5+BK5+BH5+BE5+AZ5+AW5+AT5+AQ5+AN5+AK5+AH5+AE5+Z5+W5+T5+Q5+N5+K5+H5+E5 -> 0
A6: 3 | B6: HBs ICT | C6: 0 | D6: 250 | F6: =C6+D6+-E6 -> 250 | G6: 500 | S6: 150 | V6: 250 | Y6: 350 | AA6: 3 | AB6: HBs ICT | AD6: 300 | AJ6: 75 | AP6: 250 | AS6: 250 | AV6: 200 | AY6: 500 | BA6: 3 | BB6: HBs ICT | CA6: 3 | CB6: HBs ICT | CX6: =CU6+CR6+CO6+CL6+CI6+CF6+CC6+BX6+BU6+BR6+BO6+BO6+BO6+BO6+BL6+BI6+BF6+BC6+AX6+AU6+AR6+AO6+AL6+AI6+AF6+AC6+X6+U6+R6+O6+L6+I6+F6+C6 -> 250 | CY6: =CV6+CS6+CP6+CM6+CJ6+CG6+CD6+BY6+BV6+BS6+BP6+BP6+BP6+BP6+BM6+BJ6+BG6+BD6+AY6+AV6+AS6+AP6+AM6+AJ6+AG6+AD6+Y6+V6+S6+P6+M6+J6+G6+D6 -> 3075 | CZ6: =CW6+CT6+CQ6+CN6+CK6+CH6+CE6+BZ6+BW6+BT6+BQ6+BQ6+BQ6+BQ6+BN6+BK6+BH6+BE6+AZ6+AW6+AT6+AQ6+AN6+AK6+AH6+AE6+Z6+W6+T6+Q6+N6+K6+H6+E6 -> 0
A7: 4 | B7: HCV ICT | C7: 0 | D7: 250 | F7: =C7+D7+-E7 -> 250 | G7: 500 | J7: 250 | S7: 150 | V7: 250 | Y7: 350 | AA7: 4 | AB7: HCV ICT | AD7: 300 | AJ7: 75 | AP7: 250 | AS7: 250 | AV7: 200 | AY7: 500 | BA7: 4 | BB7: HCV ICT | CA7: 4 | CB7: HCV ICT | CX7: =CU7+CR7+CO7+CL7+CI7+CF7+CC7+BX7+BU7+BR7+BO7+BO7+BO7+BO7+BL7+BI7+BF7+BC7+AX7+AU7+AR7+AO7+AL7+AI7+AF7+AC7+X7+U7+R7+O7+L7+I7+F7+C7 -> 250 | CY7: =CV7+CS7+CP7+CM7+CJ7+CG7+CD7+BY7+BV7+BS7+BP7+BP7+BP7+BP7+BM7+BJ7+BG7+BD7+AY7+AV7+AS7+AP7+AM7+AJ7+AG7+AD7+Y7+V7+S7+P7+M7+J7+G7+D7 -> 3325 | CZ7: =CW7+CT7+CQ7+CN7+CK7+CH7+CE7+BZ7+BW7+BT7+BQ7+BQ7+BQ7+BQ7+BN7+BK7+BH7+BE7+AZ7+AW7+AT7+AQ7+AN7+AK7+AH7+AE7+Z7+W7+T7+Q7+N7+K7+H7+E7 -> 0
A8: 5 | B8: STD/HIV ICT | C8: 0 | D8: 50 | F8: =C8+D8+-E8 -> 50 | G8: 50 | J8: 50 | V8: 50 | Y8: 50 | AA8: 5 | AB8: STD/HIV ICT | AD8: 50 | AJ8: 50 | AP8: 50 | AS8: 50 | AY8: 50 | BA8: 5 | BB8: STD/HIV ICT | CA8: 5 | CB8: STD/HIV ICT | CX8: =CU8+CR8+CO8+CL8+CI8+CF8+CC8+BX8+BU8+BR8+BO8+BO8+BO8+BO8+BL8+BI8+BF8+BC8+AX8+AU8+AR8+AO8+AL8+AI8+AF8+AC8+X8+U8+R8+O8+L8+I8+F8+C8 -> 50 | CY8: =CV8+CS8+CP8+CM8+CJ8+CG8+CD8+BY8+BV8+BS8+BP8+BP8+BP8+BP8+BM8+BJ8+BG8+BD8+AY8+AV8+AS8+AP8+AM8+AJ8+AG8+AD8+Y8+V8+S8+P8+M8+J8+G8+D8 -> 500 | CZ8: =CW8+CT8+CQ8+CN8+CK8+CH8+CE8+BZ8+BW8+BT8+BQ8+BQ8+BQ8+BQ8+BN8+BK8+BH8+BE8+AZ8+AW8+AT8+AQ8+AN8+AK8+AH8+AE8+Z8+W8+T8+Q8+N8+K8+H8+E8 -> 0
A9: 6 | B9: VDRL | C9: 21 | F9: =C9+D9+-E9 -> 21 | S9: 50 | V9: 50 | AA9: 6 | AB9: VDRL | AP9: 50 | AS9: 50 | AY9: 50 | BA9: 6 | BB9: VDRL | CA9: 6 | CB9: VDRL | CX9: =CU9+CR9+CO9+CL9+CI9+CF9+CC9+BX9+BU9+BR9+BO9+BO9+BO9+BO9+BL9+BI9+BF9+BC9+AX9+AU9+AR9+AO9+AL9+AI9+AF9+AC9+X9+U9+R9+O9+L9+I9+F9+C9 -> 42 | CY9: =CV9+CS9+CP9+CM9+CJ9+CG9+CD9+BY9+BV9+BS9+BP9+BP9+BP9+BP9+BM9+BJ9+BG9+BD9+AY9+AV9+AS9+AP9+AM9+AJ9+AG9+AD9+Y9+V9+S9+P9+M9+J9+G9+D9 -> 250 | CZ9: =CW9+CT9+CQ9+CN9+CK9+CH9+CE9+BZ9+BW9+BT9+BQ9+BQ9+BQ9+BQ9+BN9+BK9+BH9+BE9+AZ9+AW9+AT9+AQ9+AN9+AK9+AH9+AE9+Z9+W9+T9+Q9+N9+K9+H9+E9 -> 0
A10: 7 | B10: H. Pylori | C10: 6 | F10: =C10+D10+-E10 -> 6 | AA10: 7 | AB10: H. Pylori | AV10: 100 | BA10: 7 | BB10: H. Pylori | CA10: 7 | CB10: H. Pylori | CX10: =CU10+CR10+CO10+CL10+CI10+CF10+CC10+BX10+BU10+BR10+BO10+BO10+BO10+BO10+BL10+BI10+BF10+BC10+AX10+AU10+AR10+AO10+AL10+AI10+AF10+AC10+X10+U10+R10+O10+L10+I10+F10+C10 -> 12 | CY10: =CV10+CS10+CP10+CM10+CJ10+CG10+CD10+BY10+BV10+BS10+BP10+BP10+BP10+BP10+BM10+BJ10+BG10+BD10+AY10+AV10+AS10+AP10+AM10+AJ10+AG10+AD10+Y10+V10+S10+P10+M10+J10+G10+D10 -> 100 | CZ10: =CW10+CT10+CQ10+CN10+CK10+CH10+CE10+BZ10+BW10+BT10+BQ10+BQ10+BQ10+BQ10+BN10+BK10+BH10+BE10+AZ10+AW10+AT10+AQ10+AN10+AK10+AH10+AE10+Z10+W10+T10+Q10+N10+K10+H10+E10 -> 0
A11: 8 | B11: DENGE NS1 | C11: 15 | F11: =C11+D11+-E11 -> 15 | S11: 30 | AA11: 8 | AB11: DENGE NS1 | AJ11: 30 | AY11: 30 | BA11: 8 | BB11: DENGE NS1 | CA11: 8 | CB11: DENGE NS1 | CX11: =CU11+CR11+CO11+CL11+CI11+CF11+CC11+BX11+BU11+BR11+BO11+BO11+BO11+BO11+BL11+BI11+BF11+BC11+AX11+AU11+AR11+AO11+AL11+AI11+AF11+AC11+X11+U11+R11+O11+L11+I11+F11+C11 -> 30 | CY11: =CV11+CS11+CP11+CM11+CJ11+CG11+CD11+BY11+BV11+BS11+BP11+BP11+BP11+BP11+BM11+BJ11+BG11+BD11+AY11+AV11+AS11+AP11+AM11+AJ11+AG11+AD11+Y11+V11+S11+P11+M11+J11+G11+D11 -> 90 | CZ11: =CW11+CT11+CQ11+CN11+CK11+CH11+CE11+BZ11+BW11+BT11+BQ11+BQ11+BQ11+BQ11+BN11+BK11+BH11+BE11+AZ11+AW11+AT11+AQ11+AN11+AK11+AH11+AE11+Z11+W11+T11+Q11+N11+K11+H11+E11 -> 0
A12: 9 | B12: DENGE IGM | C12: 0 | F12: =C12+D12+-E12 -> 0 | AA12: 9 | AB12: DENGE IGM | BA12: 9 | BB12: DENGE IGM | CA12: 9 | CB12: DENGE IGM | CX12: =CU12+CR12+CO12+CL12+CI12+CF12+CC12+BX12+BU12+BR12+BO12+BO12+BO12+BO12+BL12+BI12+BF12+BC12+AX12+AU12+AR12+AO12+AL12+AI12+AF12+AC12+X12+U12+R12+O12+L12+I12+F12+C12 -> 0 | CY12: =CV12+CS12+CP12+CM12+CJ12+CG12+CD12+BY12+BV12+BS12+BP12+BP12+BP12+BP12+BM12+BJ12+BG12+BD12+AY12+AV12+AS12+AP12+AM12+AJ12+AG12+AD12+Y12+V12+S12+P12+M12+J12+G12+D12 -> 0 | CZ12: =CW12+CT12+CQ12+CN12+CK12+CH12+CE12+BZ12+BW12+BT12+BQ12+BQ12+BQ12+BQ12+BN12+BK12+BH12+BE12+AZ12+AW12+AT12+AQ12+AN12+AK12+AH12+AE12+Z12+W12+T12+Q12+N12+K12+H12+E12 -> 0
A13: 10 | B13: BSR | C13: 1000 | F13: =C13+D13+-E13 -> 1000 | AA13: 10 | AB13: BSR | BA13: 10 | BB13: BSR | CA13: 10 | CB13: BSR | CX13: =CU13+CR13+CO13+CL13+CI13+CF13+CC13+BX13+BU13+BR13+BO13+BO13+BO13+BO13+BL13+BI13+BF13+BC13+AX13+AU13+AR13+AO13+AL13+AI13+AF13+AC13+X13+U13+R13+O13+L13+I13+F13+C13 -> 2000 | CY13: =CV13+CS13+CP13+CM13+CJ13+CG13+CD13+BY13+BV13+BS13+BP13+BP13+BP13+BP13+BM13+BJ13+BG13+BD13+AY13+AV13+AS13+AP13+AM13+AJ13+AG13+AD13+Y13+V13+S13+P13+M13+J13+G13+D13 -> 0 | CZ13: =CW13+CT13+CQ13+CN13+CK13+CH13+CE13+BZ13+BW13+BT13+BQ13+BQ13+BQ13+BQ13+BN13+BK13+BH13+BE13+AZ13+AW13+AT13+AQ13+AN13+AK13+AH13+AE13+Z13+W13+T13+Q13+N13+K13+H13+E13 -> 0
A14: 11 | B14: UREA UV | F14: =C14+D14+-E14 -> 0 | J14: 1 | AA14: 11 | AB14: UREA UV | AJ14: 1 | BA14: 11 | BB14: UREA UV | CA14: 11 | CB14: UREA UV | CX14: =CU14+CR14+CO14+CL14+CI14+CF14+CC14+BX14+BU14+BR14+BO14+BO14+BO14+BO14+BL14+BI14+BF14+BC14+AX14+AU14+AR14+AO14+AL14+AI14+AF14+AC14+X14+U14+R14+O14+L14+I14+F14+C14 -> 0 | CY14: =CV14+CS14+CP14+CM14+CJ14+CG14+CD14+BY14+BV14+BS14+BP14+BP14+BP14+BP14+BM14+BJ14+BG14+BD14+AY14+AV14+AS14+AP14+AM14+AJ14+AG14+AD14+Y14+V14+S14+P14+M14+J14+G14+D14 -> 2 | CZ14: =CW14+CT14+CQ14+CN14+CK14+CH14+CE14+BZ14+BW14+BT14+BQ14+BQ14+BQ14+BQ14+BN14+BK14+BH14+BE14+AZ14+AW14+AT14+AQ14+AN14+AK14+AH14+AE14+Z14+W14+T14+Q14+N14+K14+H14+E14 -> 0
A15: 12 | B15: CRETININE | F15: =C15+D15+-E15 -> 0 | G15: 1 | Y15: 1 | AA15: 12 | AB15: CRETININE | AV15: 1 | BA15: 12 | BB15: CRETININE | CA15: 12 | CB15: CRETININE | CX15: =CU15+CR15+CO15+CL15+CI15+CF15+CC15+BX15+BU15+BR15+BO15+BO15+BO15+BO15+BL15+BI15+BF15+BC15+AX15+AU15+AR15+AO15+AL15+AI15+AF15+AC15+X15+U15+R15+O15+L15+I15+F15+C15 -> 0 | CY15: =CV15+CS15+CP15+CM15+CJ15+CG15+CD15+BY15+BV15+BS15+BP15+BP15+BP15+BP15+BM15+BJ15+BG15+BD15+AY15+AV15+AS15+AP15+AM15+AJ15+AG15+AD15+Y15+V15+S15+P15+M15+J15+G15+D15 -> 3 | CZ15: =CW15+CT15+CQ15+CN15+CK15+CH15+CE15+BZ15+BW15+BT15+BQ15+BQ15+BQ15+BQ15+BN15+BK15+BH15+BE15+AZ15+AW15+AT15+AQ15+AN15+AK15+AH15+AE15+Z15+W15+T15+Q15+N15+K15+H15+E15 -> 0
A16: 13 | B16: UREA | F16: =C16+D16+-E16 -> 0 | V16: 1 | AA16: 13 | AB16: UREA | AJ16: 1 | BA16: 13 | BB16: UREA | CA16: 13 | CB16: UREA | CX16: =CU16+CR16+CO16+CL16+CI16+CF16+CC16+BX16+BU16+BR16+BO16+BO16+BO16+BO16+BL16+BI16+BF16+BC16+AX16+AU16+AR16+AO16+AL16+AI16+AF16+AC16+X16+U16+R16+O16+L16+I16+F16+C16 -> 0 | CY16: =CV16+CS16+CP16+CM16+CJ16+CG16+CD16+BY16+BV16+BS16+BP16+BP16+BP16+BP16+BM16+BJ16+BG16+BD16+AY16+AV16+AS16+AP16+AM16+AJ16+AG16+AD16+Y16+V16+S16+P16+M16+J16+G16+D16 -> 2 | CZ16: =CW16+CT16+CQ16+CN16+CK16+CH16+CE16+BZ16+BW16+BT16+BQ16+BQ16+BQ16+BQ16+BN16+BK16+BH16+BE16+AZ16+AW16+AT16+AQ16+AN16+AK16+AH16+AE16+Z16+W16+T16+Q16+N16+K16+H16+E16 -> 0
A17: 14 | B17: GPT | F17: =C17+D17+-E17 -> 0 | J17: 1 | V17: 1 | AA17: 14 | AB17: GPT | AJ17: 1 | AP17: 1 | AS17: 1 | AV17: 1 | BA17: 14 | BB17: GPT | CA17: 14 | CB17: GPT | CX17: =CU17+CR17+CO17+CL17+CI17+CF17+CC17+BX17+BU17+BR17+BO17+BO17+BO17+BO17+BL17+BI17+BF17+BC17+AX17+AU17+AR17+AO17+AL17+AI17+AF17+AC17+X17+U17+R17+O17+L17+I17+F17+C17 -> 0 | CY17: =CV17+CS17+CP17+CM17+CJ17+CG17+CD17+BY17+BV17+BS17+BP17+BP17+BP17+BP17+BM17+BJ17+BG17+BD17+AY17+AV17+AS17+AP17+AM17+AJ17+AG17+AD17+Y17+V17+S17+P17+M17+J17+G17+D17 -> 6 | CZ17: =CW17+CT17+CQ17+CN17+CK17+CH17+CE17+BZ17+BW17+BT17+BQ17+BQ17+BQ17+BQ17+BN17+BK17+BH17+BE17+AZ17+AW17+AT17+AQ17+AN17+AK17+AH17+AE17+Z17+W17+T17+Q17+N17+K17+H17+E17 -> 0
A18: 15 | B18: ALK | F18: =C18+D18+-E18 -> 0 | J18: 1 | V18: 1 | AA18: 15 | AB18: ALK | AP18: 1 | AS18: 1 | AV18: 1 | AY18: 1 | BA18: 15 | BB18: ALK | CA18: 15 | CB18: ALK | CX18: =CU18+CR18+CO18+CL18+CI18+CF18+CC18+BX18+BU18+BR18+BO18+BO18+BO18+BO18+BL18+BI18+BF18+BC18+AX18+AU18+AR18+AO18+AL18+AI18+AF18+AC18+X18+U18+R18+O18+L18+I18+F18+C18 -> 0 | CY18: =CV18+CS18+CP18+CM18+CJ18+CG18+CD18+BY18+BV18+BS18+BP18+BP18+BP18+BP18+BM18+BJ18+BG18+BD18+AY18+AV18+AS18+AP18+AM18+AJ18+AG18+AD18+Y18+V18+S18+P18+M18+J18+G18+D18 -> 6 | CZ18: =CW18+CT18+CQ18+CN18+CK18+CH18+CE18+BZ18+BW18+BT18+BQ18+BQ18+BQ18+BQ18+BN18+BK18+BH18+BE18+AZ18+AW18+AT18+AQ18+AN18+AK18+AH18+AE18+Z18+W18+T18+Q18+N18+K18+H18+E18 -> 0
A19: 16 | B19: Total Biluribin | G19: 1 | J19: 1 | AA19: 16 | AB19: Total Biluribin | AP19: 1 | AV19: 1 | BA19: 16 | BB19: Total Biluribin | CA19: 16 | CB19: Total Biluribin | CX19: =CU19+CR19+CO19+CL19+CI19+CF19+CC19+BX19+BU19+BR19+BO19+BO19+BO19+BO19+BL19+BI19+BF19+BC19+AX19+AU19+AR19+AO19+AL19+AI19+AF19+AC19+X19+U19+R19+O19+L19+I19+F19+C19 -> 0 | CY19: =CV19+CS19+CP19+CM19+CJ19+CG19+CD19+BY19+BV19+BS19+BP19+BP19+BP19+BP19+BM19+BJ19+BG19+BD19+AY19+AV19+AS19+AP19+AM19+AJ19+AG19+AD19+Y19+V19+S19+P19+M19+J19+G19+D19 -> 4 | CZ19: =CW19+CT19+CQ19+CN19+CK19+CH19+CE19+BZ19+BW19+BT19+BQ19+BQ19+BQ19+BQ19+BN19+BK19+BH19+BE19+AZ19+AW19+AT19+AQ19+AN19+AK19+AH19+AE19+Z19+W19+T19+Q19+N19+K19+H19+E19 -> 0
A20: 17 | B20: Direct Biluribin | F20: =C20+D20+-E20 -> 0 | G20: 1 | J20: 1 | V20: 1 | Y20: 1 | AA20: 17 | AB20: Direct Biluribin | AJ20: 1 | AV20: 1 | BA20: 17 | BB20: Direct Biluribin | CA20: 17 | CB20: Direct Biluribin | CX20: =CU20+CR20+CO20+CL20+CI20+CF20+CC20+BX20+BU20+BR20+BO20+BO20+BO20+BO20+BL20+BI20+BF20+BC20+AX20+AU20+AR20+AO20+AL20+AI20+AF20+AC20+X20+U20+R20+O20+L20+I20+F20+C20 -> 0 | CY20: =CV20+CS20+CP20+CM20+CJ20+CG20+CD20+BY20+BV20+BS20+BP20+BP20+BP20+BP20+BM20+BJ20+BG20+BD20+AY20+AV20+AS20+AP20+AM20+AJ20+AG20+AD20+Y20+V20+S20+P20+M20+J20+G20+D20 -> 6 | CZ20: =CW20+CT20+CQ20+CN20+CK20+CH20+CE20+BZ20+BW20+BT20+BQ20+BQ20+BQ20+BQ20+BN20+BK20+BH20+BE20+AZ20+AW20+AT20+AQ20+AN20+AK20+AH20+AE20+Z20+W20+T20+Q20+N20+K20+H20+E20 -> 0
A21: 18 | B21: ELECTROLYTES | F21: =C21+D21+-E21 -> 0 | AA21: 18 | AB21: ELECTROLYTES | AV21: 1 | BA21: 18 | BB21: ELECTROLYTES | CA21: 18 | CB21: ELECTROLYTES | CX21: =CU21+CR21+CO21+CL21+CI21+CF21+CC21+BX21+BU21+BR21+BO21+BO21+BO21+BO21+BL21+BI21+BF21+BC21+AX21+AU21+AR21+AO21+AL21+AI21+AF21+AC21+X21+U21+R21+O21+L21+I21+F21+C21 -> 0 | CY21: =CV21+CS21+CP21+CM21+CJ21+CG21+CD21+BY21+BV21+BS21+BP21+BP21+BP21+BP21+BM21+BJ21+BG21+BD21+AY21+AV21+AS21+AP21+AM21+AJ21+AG21+AD21+Y21+V21+S21+P21+M21+J21+G21+D21 -> 1 | CZ21: =CW21+CT21+CQ21+CN21+CK21+CH21+CE21+BZ21+BW21+BT21+BQ21+BQ21+BQ21+BQ21+BN21+BK21+BH21+BE21+AZ21+AW21+AT21+AQ21+AN21+AK21+AH21+AE21+Z21+W21+T21+Q21+N21+K21+H21+E21 -> 0
A22: 19 | B22: ANTI SERA SET | F22: =C22+D22+-E22 -> 0 | AA22: 19 | AB22: ANTI SERA SET | AD22: 1 | BA22: 19 | BB22: ANTI SERA SET | CA22: 19 | CB22: ANTI SERA SET | CX22: =CU22+CR22+CO22+CL22+CI22+CF22+CC22+BX22+BU22+BR22+BO22+BO22+BO22+BO22+BL22+BI22+BF22+BC22+AX22+AU22+AR22+AO22+AL22+AI22+AF22+AC22+X22+U22+R22+O22+L22+I22+F22+C22 -> 0 | CY22: =CV22+CS22+CP22+CM22+CJ22+CG22+CD22+BY22+BV22+BS22+BP22+BP22+BP22+BP22+BM22+BJ22+BG22+BD22+AY22+AV22+AS22+AP22+AM22+AJ22+AG22+AD22+Y22+V22+S22+P22+M22+J22+G22+D22 -> 1 | CZ22: =CW22+CT22+CQ22+CN22+CK22+CH22+CE22+BZ22+BW22+BT22+BQ22+BQ22+BQ22+BQ22+BN22+BK22+BH22+BE22+AZ22+AW22+AT22+AQ22+AN22+AK22+AH22+AE22+Z22+W22+T22+Q22+N22+K22+H22+E22 -> 0
A23: 20 | B23: PT INR | F23: =C23+D23+-E23 -> 0 | AA23: 20 | AB23: PT INR | AG23: 1 | AJ23: 1 | AV23: 1 | BA23: 20 | BB23: PT INR | CA23: 20 | CB23: PT INR | CX23: =CU23+CR23+CO23+CL23+CI23+CF23+CC23+BX23+BU23+BR23+BO23+BO23+BO23+BO23+BL23+BI23+BF23+BC23+AX23+AU23+AR23+AO23+AL23+AI23+AF23+AC23+X23+U23+R23+O23+L23+I23+F23+C23 -> 0 | CY23: =CV23+CS23+CP23+CM23+CJ23+CG23+CD23+BY23+BV23+BS23+BP23+BP23+BP23+BP23+BM23+BJ23+BG23+BD23+AY23+AV23+AS23+AP23+AM23+AJ23+AG23+AD23+Y23+V23+S23+P23+M23+J23+G23+D23 -> 3 | CZ23: =CW23+CT23+CQ23+CN23+CK23+CH23+CE23+BZ23+BW23+BT23+BQ23+BQ23+BQ23+BQ23+BN23+BK23+BH23+BE23+AZ23+AW23+AT23+AQ23+AN23+AK23+AH23+AE23+Z23+W23+T23+Q23+N23+K23+H23+E23 -> 0
A24: 21 | B24: APTT | F24: =C24+D24+-E24 -> 0 | AA24: 21 | AB24: APTT | AG24: 1 | AJ24: 1 | AV24: 1 | BA24: 21 | BB24: APTT | CA24: 21 | CB24: APTT | CX24: =CU24+CR24+CO24+CL24+CI24+CF24+CC24+BX24+BU24+BR24+BO24+BO24+BO24+BO24+BL24+BI24+BF24+BC24+AX24+AU24+AR24+AO24+AL24+AI24+AF24+AC24+X24+U24+R24+O24+L24+I24+F24+C24 -> 0 | CY24: =CV24+CS24+CP24+CM24+CJ24+CG24+CD24+BY24+BV24+BS24+BP24+BP24+BP24+BP24+BM24+BJ24+BG24+BD24+AY24+AV24+AS24+AP24+AM24+AJ24+AG24+AD24+Y24+V24+S24+P24+M24+J24+G24+D24 -> 3 | CZ24: =CW24+CT24+CQ24+CN24+CK24+CH24+CE24+BZ24+BW24+BT24+BQ24+BQ24+BQ24+BQ24+BN24+BK24+BH24+BE24+AZ24+AW24+AT24+AQ24+AN24+AK24+AH24+AE24+Z24+W24+T24+Q24+N24+K24+H24+E24 -> 0
A25: 22 | B25: URINE DR | F25: =C25+D25+-E25 -> 0 | AA25: 22 | AB25: URINE DR | BA25: 22 | BB25: URINE DR | CA25: 22 | CB25: URINE DR | CE25: =#REF! -> #REF! | CH25: =#REF! -> #REF! | CK25: =#REF! -> #REF! | CN25: =#REF! -> #REF! | CQ25: =#REF! -> #REF! | CT25: =#REF! -> #REF! | CX25: =CU25+CR25+CO25+CL25+CI25+CF25+CC25+BX25+BU25+BR25+BO25+BO25+BO25+BO25+BL25+BI25+BF25+BC25+AX25+AU25+AR25+AO25+AL25+AI25+AF25+AC25+X25+U25+R25+O25+L25+I25+F25+C25 -> 0 | CY25: =CV25+CS25+CP25+CM25+CJ25+CG25+CD25+BY25+BV25+BS25+BP25+BP25+BP25+BP25+BM25+BJ25+BG25+BD25+AY25+AV25+AS25+AP25+AM25+AJ25+AG25+AD25+Y25+V25+S25+P25+M25+J25+G25+D25 -> 0 | CZ25: =CW25+CT25+CQ25+CN25+CK25+CH25+CE25+BZ25+BW25+BT25+BQ25+BQ25+BQ25+BQ25+BN25+BK25+BH25+BE25+AZ25+AW25+AT25+AQ25+AN25+AK25+AH25+AE25+Z25+W25+T25+Q25+N25+K25+H25+E25 -> #REF!
A26: 23 | B26: URINE PT | F26: =C26+D26+-E26 -> 0 | AA26: 23 | AB26: URINE PT | AJ26: 100 | BA26: 23 | BB26: URINE PT | CA26: 23 | CB26: URINE PT | CE26: =#REF! -> #REF! | CH26: =#REF! -> #REF! | CK26: =#REF! -> #REF! | CN26: =#REF! -> #REF! | CQ26: =#REF! -> #REF! | CT26: =#REF! -> #REF! | CX26: =CU26+CR26+CO26+CL26+CI26+CF26+CC26+BX26+BU26+BR26+BO26+BO26+BO26+BO26+BL26+BI26+BF26+BC26+AX26+AU26+AR26+AO26+AL26+AI26+AF26+AC26+X26+U26+R26+O26+L26+I26+F26+C26 -> 0 | CY26: =CV26+CS26+CP26+CM26+CJ26+CG26+CD26+BY26+BV26+BS26+BP26+BP26+BP26+BP26+BM26+BJ26+BG26+BD26+AY26+AV26+AS26+AP26+AM26+AJ26+AG26+AD26+Y26+V26+S26+P26+M26+J26+G26+D26 -> 100 | CZ26: =CW26+CT26+CQ26+CN26+CK26+CH26+CE26+BZ26+BW26+BT26+BQ26+BQ26+BQ26+BQ26+BN26+BK26+BH26+BE26+AZ26+AW26+AT26+AQ26+AN26+AK26+AH26+AE26+Z26+W26+T26+Q26+N26+K26+H26+E26 -> #REF!
A27: 24 | B27: BT CT | F27: =C27+D27+-E27 -> 0 | AA27: 24 | AB27: BT CT | BA27: 24 | BB27: BT CT | CA27: 24 | CB27: BT CT | CX27: =CU27+CR27+CO27+CL27+CI27+CF27+CC27+BX27+BU27+BR27+BO27+BO27+BO27+BO27+BL27+BI27+BF27+BC27+AX27+AU27+AR27+AO27+AL27+AI27+AF27+AC27+X27+U27+R27+O27+L27+I27+F27+C27 -> 0 | CY27: =CV27+CS27+CP27+CM27+CJ27+CG27+CD27+BY27+BV27+BS27+BP27+BP27+BP27+BP27+BM27+BJ27+BG27+BD27+AY27+AV27+AS27+AP27+AM27+AJ27+AG27+AD27+Y27+V27+S27+P27+M27+J27+G27+D27 -> 0 | CZ27: =CW27+CT27+CQ27+CN27+CK27+CH27+CE27+BZ27+BW27+BT27+BQ27+BQ27+BQ27+BQ27+BN27+BK27+BH27+BE27+AZ27+AW27+AT27+AQ27+AN27+AK27+AH27+AE27+Z27+W27+T27+Q27+N27+K27+H27+E27 -> 0
A28: 25 | B28: RA | F28: =C28+D28+-E28 -> 0 | AA28: 25 | AB28: RA | BA28: 25 | BB28: RA | CA28: 25 | CB28: RA | CX28: =CU28+CR28+CO28+CL28+CI28+CF28+CC28+BX28+BU28+BR28+BO28+BO28+BO28+BO28+BL28+BI28+BF28+BC28+AX28+AU28+AR28+AO28+AL28+AI28+AF28+AC28+X28+U28+R28+O28+L28+I28+F28+C28 -> 0 | CY28: =CV28+CS28+CP28+CM28+CJ28+CG28+CD28+BY28+BV28+BS28+BP28+BP28+BP28+BP28+BM28+BJ28+BG28+BD28+AY28+AV28+AS28+AP28+AM28+AJ28+AG28+AD28+Y28+V28+S28+P28+M28+J28+G28+D28 -> 0 | CZ28: =CW28+CT28+CQ28+CN28+CK28+CH28+CE28+BZ28+BW28+BT28+BQ28+BQ28+BQ28+BQ28+BN28+BK28+BH28+BE28+AZ28+AW28+AT28+AQ28+AN28+AK28+AH28+AE28+Z28+W28+T28+Q28+N28+K28+H28+E28 -> 0
A29: 26 | B29: ASOT | F29: =C29+D29+-E29 -> 0 | AA29: 26 | AB29: ASOT | BA29: 26 | BB29: ASOT | CA29: 26 | CB29: ASOT | CX29: =CU29+CR29+CO29+CL29+CI29+CF29+CC29+BX29+BU29+BR29+BO29+BO29+BO29+BO29+BL29+BI29+BF29+BC29+AX29+AU29+AR29+AO29+AL29+AI29+AF29+AC29+X29+U29+R29+O29+L29+I29+F29+C29 -> 0 | CY29: =CV29+CS29+CP29+CM29+CJ29+CG29+CD29+BY29+BV29+BS29+BP29+BP29+BP29+BP29+BM29+BJ29+BG29+BD29+AY29+AV29+AS29+AP29+AM29+AJ29+AG29+AD29+Y29+V29+S29+P29+M29+J29+G29+D29 -> 0 | CZ29: =CW29+CT29+CQ29+CN29+CK29+CH29+CE29+BZ29+BW29+BT29+BQ29+BQ29+BQ29+BQ29+BN29+BK29+BH29+BE29+AZ29+AW29+AT29+AQ29+AN29+AK29+AH29+AE29+Z29+W29+T29+Q29+N29+K29+H29+E29 -> 0
A30: 27 | B30: S. CUP | F30: =C30+D30+-E30 -> 0 | J30: 1 | S30: 1 | AA30: 27 | AB30: S. CUP | AD30: 500 | AJ30: 500 | AP30: 500 | AV30: 500 | AY30: 500 | BA30: 27 | BB30: S. CUP | CA30: 27 | CB30: S. CUP | CX30: =CU30+CR30+CO30+CL30+CI30+CF30+CC30+BX30+BU30+BR30+BO30+BO30+BO30+BO30+BL30+BI30+BF30+BC30+AX30+AU30+AR30+AO30+AL30+AI30+AF30+AC30+X30+U30+R30+O30+L30+I30+F30+C30 -> 0 | CY30: =CV30+CS30+CP30+CM30+CJ30+CG30+CD30+BY30+BV30+BS30+BP30+BP30+BP30+BP30+BM30+BJ30+BG30+BD30+AY30+AV30+AS30+AP30+AM30+AJ30+AG30+AD30+Y30+V30+S30+P30+M30+J30+G30+D30 -> 2502 | CZ30: =CW30+CT30+CQ30+CN30+CK30+CH30+CE30+BZ30+BW30+BT30+BQ30+BQ30+BQ30+BQ30+BN30+BK30+BH30+BE30+AZ30+AW30+AT30+AQ30+AN30+AK30+AH30+AE30+Z30+W30+T30+Q30+N30+K30+H30+E30 -> 0
A31: 28 | B31: URIC ACID | F31: =C31+D31+-E31 -> 0 | Y31: 1 | AA31: 28 | AB31: URIC ACID | BA31: 28 | BB31: URIC ACID | CA31: 28 | CB31: URIC ACID | CX31: =CU31+CR31+CO31+CL31+CI31+CF31+CC31+BX31+BU31+BR31+BO31+BO31+BO31+BO31+BL31+BI31+BF31+BC31+AX31+AU31+AR31+AO31+AL31+AI31+AF31+AC31+X31+U31+R31+O31+L31+I31+F31+C31 -> 0 | CY31: =CV31+CS31+CP31+CM31+CJ31+CG31+CD31+BY31+BV31+BS31+BP31+BP31+BP31+BP31+BM31+BJ31+BG31+BD31+AY31+AV31+AS31+AP31+AM31+AJ31+AG31+AD31+Y31+V31+S31+P31+M31+J31+G31+D31 -> 1 | CZ31: =CW31+CT31+CQ31+CN31+CK31+CH31+CE31+BZ31+BW31+BT31+BQ31+BQ31+BQ31+BQ31+BN31+BK31+BH31+BE31+AZ31+AW31+AT31+AQ31+AN31+AK31+AH31+AE31+Z31+W31+T31+Q31+N31+K31+H31+E31 -> 0
A32: 29 | B32: HBA 1C | F32: =C32+D32+-E32 -> 0 | AA32: 29 | AB32: HBA 1C | BA32: 29 | BB32: HBA 1C | CA32: 29 | CB32: HBA 1C | CX32: =CU32+CR32+CO32+CL32+CI32+CF32+CC32+BX32+BU32+BR32+BO32+BO32+BO32+BO32+BL32+BI32+BF32+BC32+AX32+AU32+AR32+AO32+AL32+AI32+AF32+AC32+X32+U32+R32+O32+L32+I32+F32+C32 -> 0 | CY32: =CV32+CS32+CP32+CM32+CJ32+CG32+CD32+BY32+BV32+BS32+BP32+BP32+BP32+BP32+BM32+BJ32+BG32+BD32+AY32+AV32+AS32+AP32+AM32+AJ32+AG32+AD32+Y32+V32+S32+P32+M32+J32+G32+D32 -> 0 | CZ32: =CW32+CT32+CQ32+CN32+CK32+CH32+CE32+BZ32+BW32+BT32+BQ32+BQ32+BQ32+BQ32+BN32+BK32+BH32+BE32+AZ32+AW32+AT32+AQ32+AN32+AK32+AH32+AE32+Z32+W32+T32+Q32+N32+K32+H32+E32 -> 0
A33: 30 | B33: S. CHOLESTROL | F33: =C33+D33+-E33 -> 0 | AA33: 30 | AB33: S. CHOLESTROL | AJ33: 1 | AS33: 1 | BA33: 30 | BB33: S. CHOLESTROL | CA33: 30 | CB33: S. CHOLESTROL | CX33: =CU33+CR33+CO33+CL33+CI33+CF33+CC33+BX33+BU33+BR33+BO33+BO33+BO33+BO33+BL33+BI33+BF33+BC33+AX33+AU33+AR33+AO33+AL33+AI33+AF33+AC33+X33+U33+R33+O33+L33+I33+F33+C33 -> 0 | CY33: =CV33+CS33+CP33+CM33+CJ33+CG33+CD33+BY33+BV33+BS33+BP33+BP33+BP33+BP33+BM33+BJ33+BG33+BD33+AY33+AV33+AS33+AP33+AM33+AJ33+AG33+AD33+Y33+V33+S33+P33+M33+J33+G33+D33 -> 2 | CZ33: =CW33+CT33+CQ33+CN33+CK33+CH33+CE33+BZ33+BW33+BT33+BQ33+BQ33+BQ33+BQ33+BN33+BK33+BH33+BE33+AZ33+AW33+AT33+AQ33+AN33+AK33+AH33+AE33+Z33+W33+T33+Q33+N33+K33+H33+E33 -> 0
A34: 31 | B34: S. CALCIUM | F34: =C34+D34+-E34 -> 0 | Y34: 1 | AA34: 31 | AB34: S. CALCIUM | BA34: 31 | BB34: S. CALCIUM | CA34: 31 | CB34: S. CALCIUM | CX34: =CU34+CR34+CO34+CL34+CI34+CF34+CC34+BX34+BU34+BR34+BO34+BO34+BO34+BO34+BL34+BI34+BF34+BC34+AX34+AU34+AR34+AO34+AL34+AI34+AF34+AC34+X34+U34+R34+O34+L34+I34+F34+C34 -> 0 | CY34: =CV34+CS34+CP34+CM34+CJ34+CG34+CD34+BY34+BV34+BS34+BP34+BP34+BP34+BP34+BM34+BJ34+BG34+BD34+AY34+AV34+AS34+AP34+AM34+AJ34+AG34+AD34+Y34+V34+S34+P34+M34+J34+G34+D34 -> 1 | CZ34: =CW34+CT34+CQ34+CN34+CK34+CH34+CE34+BZ34+BW34+BT34+BQ34+BQ34+BQ34+BQ34+BN34+BK34+BH34+BE34+AZ34+AW34+AT34+AQ34+AN34+AK34+AH34+AE34+Z34+W34+T34+Q34+N34+K34+H34+E34 -> 0
A35: 32 | B35: S. AMYLYSIS | F35: =C35+D35+-E35 -> 0 | AA35: 32 | AB35: S. AMYLYSIS | BA35: 32 | BB35: S. AMYLYSIS | CA35: 32 | CB35: S. AMYLYSIS | CX35: =CU35+CR35+CO35+CL35+CI35+CF35+CC35+BX35+BU35+BR35+BO35+BO35+BO35+BO35+BL35+BI35+BF35+BC35+AX35+AU35+AR35+AO35+AL35+AI35+AF35+AC35+X35+U35+R35+O35+L35+I35+F35+C35 -> 0 | CY35: =CV35+CS35+CP35+CM35+CJ35+CG35+CD35+BY35+BV35+BS35+BP35+BP35+BP35+BP35+BM35+BJ35+BG35+BD35+AY35+AV35+AS35+AP35+AM35+AJ35+AG35+AD35+Y35+V35+S35+P35+M35+J35+G35+D35 -> 0 | CZ35: =CW35+CT35+CQ35+CN35+CK35+CH35+CE35+BZ35+BW35+BT35+BQ35+BQ35+BQ35+BQ35+BN35+BK35+BH35+BE35+AZ35+AW35+AT35+AQ35+AN35+AK35+AH35+AE35+Z35+W35+T35+Q35+N35+K35+H35+E35 -> 0
A36: 33 | B36: S. ALBUMIN | F36: =C36+D36+-E36 -> 0 | Y36: 1 | AA36: 33 | AB36: S. ALBUMIN | AP36: 1 | BA36: 33 | BB36: S. ALBUMIN | CA36: 33 | CB36: S. ALBUMIN | CX36: =CU36+CR36+CO36+CL36+CI36+CF36+CC36+BX36+BU36+BR36+BO36+BO36+BO36+BO36+BL36+BI36+BF36+BC36+AX36+AU36+AR36+AO36+AL36+AI36+AF36+AC36+X36+U36+R36+O36+L36+I36+F36+C36 -> 0 | CY36: =CV36+CS36+CP36+CM36+CJ36+CG36+CD36+BY36+BV36+BS36+BP36+BP36+BP36+BP36+BM36+BJ36+BG36+BD36+AY36+AV36+AS36+AP36+AM36+AJ36+AG36+AD36+Y36+V36+S36+P36+M36+J36+G36+D36 -> 2 | CZ36: =CW36+CT36+CQ36+CN36+CK36+CH36+CE36+BZ36+BW36+BT36+BQ36+BQ36+BQ36+BQ36+BN36+BK36+BH36+BE36+AZ36+AW36+AT36+AQ36+AN36+AK36+AH36+AE36+Z36+W36+T36+Q36+N36+K36+H36+E36 -> 0
A37: 34 | B37: CSF | F37: =C37+D37+-E37 -> 0 | AA37: 34 | AB37: CSF | BA37: 34 | BB37: CSF | CA37: 34 | CB37: CSF | CX37: =CU37+CR37+CO37+CL37+CI37+CF37+CC37+BX37+BU37+BR37+BO37+BO37+BO37+BO37+BL37+BI37+BF37+BC37+AX37+AU37+AR37+AO37+AL37+AI37+AF37+AC37+X37+U37+R37+O37+L37+I37+F37+C37 -> 0 | CY37: =CV37+CS37+CP37+CM37+CJ37+CG37+CD37+BY37+BV37+BS37+BP37+BP37+BP37+BP37+BM37+BJ37+BG37+BD37+AY37+AV37+AS37+AP37+AM37+AJ37+AG37+AD37+Y37+V37+S37+P37+M37+J37+G37+D37 -> 0 | CZ37: =CW37+CT37+CQ37+CN37+CK37+CH37+CE37+BZ37+BW37+BT37+BQ37+BQ37+BQ37+BQ37+BN37+BK37+BH37+BE37+AZ37+AW37+AT37+AQ37+AN37+AK37+AH37+AE37+Z37+W37+T37+Q37+N37+K37+H37+E37 -> 0
A38: 35 | B38: ABG S | F38: =C38+D38+-E38 -> 0 | S38: 1 | AA38: 35 | AB38: ABG S | BA38: 35 | BB38: ABG S | CA38: 35 | CB38: ABG S | CX38: =CU38+CR38+CO38+CL38+CI38+CF38+CC38+BX38+BU38+BR38+BO38+BO38+BO38+BO38+BL38+BI38+BF38+BC38+AX38+AU38+AR38+AO38+AL38+AI38+AF38+AC38+X38+U38+R38+O38+L38+I38+F38+C38 -> 0 | CY38: =CV38+CS38+CP38+CM38+CJ38+CG38+CD38+BY38+BV38+BS38+BP38+BP38+BP38+BP38+BM38+BJ38+BG38+BD38+AY38+AV38+AS38+AP38+AM38+AJ38+AG38+AD38+Y38+V38+S38+P38+M38+J38+G38+D38 -> 1 | CZ38: =CW38+CT38+CQ38+CN38+CK38+CH38+CE38+BZ38+BW38+BT38+BQ38+BQ38+BQ38+BQ38+BN38+BK38+BH38+BE38+AZ38+AW38+AT38+AQ38+AN38+AK38+AH38+AE38+Z38+W38+T38+Q38+N38+K38+H38+E38 -> 0
A39: 36 | B39: CBC TUBES | D39: 300 | F39: =C39+D39+-E39 -> 300 | G39: 600 | J39: 400 | S39: 300 | V39: 400 | Y39: 400 | AA39: 36 | AB39: CBC TUBES | AD39: 600 | AJ39: 600 | AP39: 400 | AS39: 400 | AV39: 300 | AY39: 600 | BA39: 36 | BB39: CBC TUBES | CA39: 36 | CB39: CBC TUBES | CX39: =CU39+CR39+CO39+CL39+CI39+CF39+CC39+BX39+BU39+BR39+BO39+BO39+BO39+BO39+BL39+BI39+BF39+BC39+AX39+AU39+AR39+AO39+AL39+AI39+AF39+AC39+X39+U39+R39+O39+L39+I39+F39+C39 -> 300 | CY39: =CV39+CS39+CP39+CM39+CJ39+CG39+CD39+BY39+BV39+BS39+BP39+BP39+BP39+BP39+BM39+BJ39+BG39+BD39+AY39+AV39+AS39+AP39+AM39+AJ39+AG39+AD39+Y39+V39+S39+P39+M39+J39+G39+D39 -> 5300 | CZ39: =CW39+CT39+CQ39+CN39+CK39+CH39+CE39+BZ39+BW39+BT39+BQ39+BQ39+BQ39+BQ39+BN39+BK39+BH39+BE39+AZ39+AW39+AT39+AQ39+AN39+AK39+AH39+AE39+Z39+W39+T39+Q39+N39+K39+H39+E39 -> 0
A40: 37 | B40: GEL TUBES | D40: 200 | F40: =C40+D40+-E40 -> 200 | G40: 500 | J40: 300 | S40: 200 | V40: 300 | Y40: 300 | AA40: 37 | AB40: GEL TUBES | AD40: 500 | AJ40: 400 | AP40: 300 | AS40: 300 | AV40: 300 | AY40: 600 | BA40: 37 | BB40: GEL TUBES | CA40: 37 | CB40: GEL TUBES | CX40: =CU40+CR40+CO40+CL40+CI40+CF40+CC40+BX40+BU40+BR40+BO40+BO40+BO40+BO40+BL40+BI40+BF40+BC40+AX40+AU40+AR40+AO40+AL40+AI40+AF40+AC40+X40+U40+R40+O40+L40+I40+F40+C40 -> 200 | CY40: =CV40+CS40+CP40+CM40+CJ40+CG40+CD40+BY40+BV40+BS40+BP40+BP40+BP40+BP40+BM40+BJ40+BG40+BD40+AY40+AV40+AS40+AP40+AM40+AJ40+AG40+AD40+Y40+V40+S40+P40+M40+J40+G40+D40 -> 4200 | CZ40: =CW40+CT40+CQ40+CN40+CK40+CH40+CE40+BZ40+BW40+BT40+BQ40+BQ40+BQ40+BQ40+BN40+BK40+BH40+BE40+AZ40+AW40+AT40+AQ40+AN40+AK40+AH40+AE40+Z40+W40+T40+Q40+N40+K40+H40+E40 -> 0
...
